Traceback (most recent call last):
  File "/Users/stu/git/tripschedule/triptomorrow.py", line 56, in <module>
    if not row['Booking Reference'] == "":
KeyError: 'Booking Reference'
Traceback (most recent call last):
  File "/Users/stu/git/tripschedule/triptomorrow.py", line 24, in <module>
    with smtplib.SMTP_SSL("smtp.gmail.com", 465, context=context) as server:
  File "/opt/homebrew/Cellar/python@3.9/3.9.23/Frameworks/Python.framework/Versions/3.9/lib/python3.9/smtplib.py", line 1050, in __init__
    SMTP.__init__(self, host, port, local_hostname, timeout,
  File "/opt/homebrew/Cellar/python@3.9/3.9.23/Frameworks/Python.framework/Versions/3.9/lib/python3.9/smtplib.py", line 255, in __init__
    (code, msg) = self.connect(host, port)
  File "/opt/homebrew/Cellar/python@3.9/3.9.23/Frameworks/Python.framework/Versions/3.9/lib/python3.9/smtplib.py", line 341, in connect
    self.sock = self._get_socket(host, port, self.timeout)
  File "/opt/homebrew/Cellar/python@3.9/3.9.23/Frameworks/Python.framework/Versions/3.9/lib/python3.9/smtplib.py", line 1056, in _get_socket
    new_socket = super()._get_socket(host, port, timeout)
  File "/opt/homebrew/Cellar/python@3.9/3.9.23/Frameworks/Python.framework/Versions/3.9/lib/python3.9/smtplib.py", line 312, in _get_socket
    return socket.create_connection((host, port), timeout,
  File "/opt/homebrew/Cellar/python@3.9/3.9.23/Frameworks/Python.framework/Versions/3.9/lib/python3.9/socket.py", line 835, in create_connection
    for res in getaddrinfo(host, port, 0, SOCK_STREAM):
  File "/opt/homebrew/Cellar/python@3.9/3.9.23/Frameworks/Python.framework/Versions/3.9/lib/python3.9/socket.py", line 966, in getaddrinfo
    for res in _socket.getaddrinfo(host, port, family, type, proto, flags):
socket.gaierror: [Errno 8] nodename nor servname provided, or not known
Traceback (most recent call last):
  File "/Users/stu/git/tripschedule/triptomorrow.py", line 24, in <module>
    with smtplib.SMTP_SSL("smtp.gmail.com", 465, context=context) as server:
  File "/opt/homebrew/Cellar/python@3.9/3.9.23/Frameworks/Python.framework/Versions/3.9/lib/python3.9/smtplib.py", line 1050, in __init__
    SMTP.__init__(self, host, port, local_hostname, timeout,
  File "/opt/homebrew/Cellar/python@3.9/3.9.23/Frameworks/Python.framework/Versions/3.9/lib/python3.9/smtplib.py", line 255, in __init__
    (code, msg) = self.connect(host, port)
  File "/opt/homebrew/Cellar/python@3.9/3.9.23/Frameworks/Python.framework/Versions/3.9/lib/python3.9/smtplib.py", line 341, in connect
    self.sock = self._get_socket(host, port, self.timeout)
  File "/opt/homebrew/Cellar/python@3.9/3.9.23/Frameworks/Python.framework/Versions/3.9/lib/python3.9/smtplib.py", line 1056, in _get_socket
    new_socket = super()._get_socket(host, port, timeout)
  File "/opt/homebrew/Cellar/python@3.9/3.9.23/Frameworks/Python.framework/Versions/3.9/lib/python3.9/smtplib.py", line 312, in _get_socket
    return socket.create_connection((host, port), timeout,
  File "/opt/homebrew/Cellar/python@3.9/3.9.23/Frameworks/Python.framework/Versions/3.9/lib/python3.9/socket.py", line 835, in create_connection
    for res in getaddrinfo(host, port, 0, SOCK_STREAM):
  File "/opt/homebrew/Cellar/python@3.9/3.9.23/Frameworks/Python.framework/Versions/3.9/lib/python3.9/socket.py", line 966, in getaddrinfo
    for res in _socket.getaddrinfo(host, port, family, type, proto, flags):
socket.gaierror: [Errno 8] nodename nor servname provided, or not known
Traceback (most recent call last):
  File "/Users/stu/git/tripschedule/triptomorrow.py", line 24, in <module>
    with smtplib.SMTP_SSL("smtp.gmail.com", 465, context=context) as server:
  File "/opt/homebrew/Cellar/python@3.9/3.9.23/Frameworks/Python.framework/Versions/3.9/lib/python3.9/smtplib.py", line 1050, in __init__
    SMTP.__init__(self, host, port, local_hostname, timeout,
  File "/opt/homebrew/Cellar/python@3.9/3.9.23/Frameworks/Python.framework/Versions/3.9/lib/python3.9/smtplib.py", line 255, in __init__
    (code, msg) = self.connect(host, port)
  File "/opt/homebrew/Cellar/python@3.9/3.9.23/Frameworks/Python.framework/Versions/3.9/lib/python3.9/smtplib.py", line 341, in connect
    self.sock = self._get_socket(host, port, self.timeout)
  File "/opt/homebrew/Cellar/python@3.9/3.9.23/Frameworks/Python.framework/Versions/3.9/lib/python3.9/smtplib.py", line 1056, in _get_socket
    new_socket = super()._get_socket(host, port, timeout)
  File "/opt/homebrew/Cellar/python@3.9/3.9.23/Frameworks/Python.framework/Versions/3.9/lib/python3.9/smtplib.py", line 312, in _get_socket
    return socket.create_connection((host, port), timeout,
  File "/opt/homebrew/Cellar/python@3.9/3.9.23/Frameworks/Python.framework/Versions/3.9/lib/python3.9/socket.py", line 856, in create_connection
    raise err
  File "/opt/homebrew/Cellar/python@3.9/3.9.23/Frameworks/Python.framework/Versions/3.9/lib/python3.9/socket.py", line 844, in create_connection
    sock.connect(sa)
ConnectionRefusedError: [Errno 61] Connection refused
Traceback (most recent call last):
  File "/Users/stu/git/tripschedule/triptomorrow.py", line 24, in <module>
    with smtplib.SMTP_SSL("smtp.gmail.com", 465, context=context) as server:
  File "/opt/homebrew/Cellar/python@3.9/3.9.23/Frameworks/Python.framework/Versions/3.9/lib/python3.9/smtplib.py", line 1050, in __init__
    SMTP.__init__(self, host, port, local_hostname, timeout,
  File "/opt/homebrew/Cellar/python@3.9/3.9.23/Frameworks/Python.framework/Versions/3.9/lib/python3.9/smtplib.py", line 255, in __init__
    (code, msg) = self.connect(host, port)
  File "/opt/homebrew/Cellar/python@3.9/3.9.23/Frameworks/Python.framework/Versions/3.9/lib/python3.9/smtplib.py", line 341, in connect
    self.sock = self._get_socket(host, port, self.timeout)
  File "/opt/homebrew/Cellar/python@3.9/3.9.23/Frameworks/Python.framework/Versions/3.9/lib/python3.9/smtplib.py", line 1056, in _get_socket
    new_socket = super()._get_socket(host, port, timeout)
  File "/opt/homebrew/Cellar/python@3.9/3.9.23/Frameworks/Python.framework/Versions/3.9/lib/python3.9/smtplib.py", line 312, in _get_socket
    return socket.create_connection((host, port), timeout,
  File "/opt/homebrew/Cellar/python@3.9/3.9.23/Frameworks/Python.framework/Versions/3.9/lib/python3.9/socket.py", line 856, in create_connection
    raise err
  File "/opt/homebrew/Cellar/python@3.9/3.9.23/Frameworks/Python.framework/Versions/3.9/lib/python3.9/socket.py", line 844, in create_connection
    sock.connect(sa)
ConnectionRefusedError: [Errno 61] Connection refused
